<?xml version="1.0" ?>
<mujoco model="franka_panda v200">

    <!-- =================================================
    Copyright 2018 Vikash Kumar
    Model   :: Franka (MuJoCoV2.0)
    Author  :: Vikash Kumar (vikashplus@gmail.com)
    source  :: https://github.com/vikashplus/franka_sim
    License :: Under Apache License, Version 2.0 (the "License"); you may not use this file except in compliance with the License. You may obtain a copy of the License at http://www.apache.org/licenses/LICENSE-2.0 Unless required by applicable law or agreed to in writing, software distributed under the License is distributed on an "AS IS" BASIS, WITHOUT WARRANTIES OR CONDITIONS OF ANY KIND, either express or implied. See the License for the specific language governing permissions and limitations under the License.
====================================================== -->
    <compiler angle="radian"/>
<!--    <option collision="predefined" timestep="0.005" integrator="RK4" />-->
    <option gravity="0 0 -9.81" />
    <size nconmax="100" njmax="500" nuser_actuator="5"/>
    <default class="main">

        <default class="panda">

            <joint limited="true"/>
            <default class="visual">
              <geom contype="0" conaffinity="0"/>
            </default>
            <default class="collision">
              <geom contype="1" conaffinity="1" friction=".6 0.005 0.0001"/>
            </default>
            <general biasprm="0 -1 0 0 0 0 0 0 0 0" biastype="affine" ctrllimited="true" forcelimited="true" user="1002 40 2001 -0.005 0.005"/>
            <default class="panda_viz">
                <geom conaffinity="0" contype="0" rgba="0.95 0.99 0.92 1" type="mesh"/>
                <general user="1002 40 2001 -0.005 0.005"/>
            </default>
            <default class="panda_col">
                <geom group="3" rgba="0.5 0.6 0.7 1" type="mesh"/>
                <general user="1002 40 2001 -0.005 0.005"/>
            </default>
            <default class="panda_grey_viz">
                <geom contype="0" conaffinity="0" group="0" type="mesh" rgba=".4 .4 .4 1" mass="0"/>
            </default>
            <default class="panda_arm">
                <joint damping="0.1"/>
                <general user="1002 40 2001 -0.005 0.005"/>
            </default>
            <default class="panda_forearm">
                <joint damping="0.01"/>
                <general user="1002 40 2001 -0.005 0.005"/>
            </default>
            <default class="panda_finger">
                <joint armature="5" damping="100"/>
                <geom conaffinity="0" condim="6" friction="1 0.5 0.0001" group="3" margin="0.001" rgba="0.5 0.6 0.7 0.4" solimp="0.8 0.9 0.001 0.5 2" solref="0.01 1"/>
                <general user="1002 40 2001 -0.0001 0.0001"/>
            </default>
        </default>
        <default class="panda_overlay">
            <joint armature="1" damping="1000" frictionloss="10"/>
            <geom conaffinity="0" contype="0" group="2" rgba="0.42 0.42 0.42 0.5" type="mesh"/>
        </default>
    </default>

    <asset>
        <texture type="skybox" builtin="gradient" rgb1="1 1 1" rgb2=".6 .8 1" width="256" height="256"/>
        <texture builtin="checker" height="512" name="texplane" rgb1="0.2 0.3 0.4" rgb2="0.1 0.15 0.2" type="2d" width="512"/>
        <material name="MatGnd" reflectance="0.3" texture="texplane" texuniform="true"/>
        <mesh file="./meshes/collision/link0.stl" name="link0_col"/>
        <mesh file="./meshes/collision/link1.stl" name="link1_col"/>
        <mesh file="./meshes/collision/link2.stl" name="link2_col"/>
        <mesh file="./meshes/collision/link3.stl" name="link3_col"/>
        <mesh file="./meshes/collision/link4.stl" name="link4_col"/>
        <mesh file="./meshes/collision/link5.stl" name="link5_col"/>
        <mesh file="./meshes/collision/link6.stl" name="link6_col"/>
        <mesh file="./meshes/collision/link7.stl" name="link7_col"/>
        <mesh file="./meshes/collision/hand.stl" name="hand_col"/>
        <mesh file="./meshes/visual/link0.stl" name="link0_viz"/>
        <mesh file="./meshes/visual/link1.stl" name="link1_viz"/>
        <mesh file="./meshes/visual/link2.stl" name="link2_viz"/>
        <mesh file="./meshes/visual/link3.stl" name="link3_viz"/>
        <mesh file="./meshes/visual/link4.stl" name="link4_viz"/>
        <mesh file="./meshes/visual/link5.stl" name="link5_viz"/>
        <mesh file="./meshes/visual/link6.stl" name="link6_viz"/>
        <mesh file="./meshes/visual/link7.stl" name="link7_viz"/>
        <mesh file="./meshes/visual/hand.stl" name="hand_viz"/>
        <mesh name="kuka_link_0_mesh" file="./meshes/visual/kuka_link_0.stl"/>
        <mesh name="kuka_link_1_mesh" file="./meshes/visual/kuka_link_1.stl"/>
        <mesh name="kuka_link_2_mesh" file="./meshes/visual/kuka_link_2.stl"/>
        <mesh name="kuka_link_3_mesh" file="./meshes/visual/kuka_link_3.stl"/>
        <mesh name="kuka_link_4_mesh" file="./meshes/visual/kuka_link_4.stl"/>
        <mesh name="kuka_link_5_mesh" file="./meshes/visual/kuka_link_5.stl"/>
        <mesh name="kuka_link_6_mesh" file="./meshes/visual/kuka_link_6.stl"/>
        <mesh name="kuka_link_7_mesh" file="./meshes/visual/kuka_link_7.stl"/>
        <material name="kuka_orange" rgba="1.0 0.423529411765 0.0392156862745 1.0"/>
        <material name="kuka_grey" rgba="0.4 0.4 0.4 1.0"/>
        <mesh file="./meshes/visual/link3_dark.stl" name="link3_dark_viz" scale="1.01 1.01 1.01"/>
        <mesh file="./meshes/visual/link4_dark.stl" name="link4_dark_viz" scale="1.01 1.01 1.01"/>
        <mesh file="./meshes/visual/link5_dark.stl" name="link5_dark_viz" scale="1.01 1.01 1.01"/>
        <mesh file="./meshes/visual/link6_dark.stl" name="link6_dark_viz" scale="1.01 1.01 1.01"/>
        <mesh file="./meshes/visual/link7_dark.stl" name="link7_dark_viz" scale="1.01 1.01 1.01"/>
        <mesh file="./meshes/collision/finger.stl" name="finger_col" scale="1.75 1 1.75"/>
        <mesh file="./meshes/collision/finger.stl" name="finger_viz" scale="1.75 1 1.75"/>

        <texture name="light_wood_v3" file="./textures/light_wood_v3.png" type="2d"/>
        <material shininess=".1" name="light_wood_v3" texture="light_wood_v3" specular="0.4"/>

        <texture name="marble" file="./textures/marble.png" type="2d"/>
        <material shininess=".1" name="marble" texture="marble" specular="0.4"/>
    </asset>

    <worldbody>
        <camera name="cam" mode="fixed" pos="1.65 0 3.0" quat="0.683 0.183 0.183 0.683"/>
        <light diffuse="0.8 0.8 0.8" dir="-0.301511 -0.301511 -0.904534" specular="0.3 0.3 0.3" pos="1.5 1 3" castshadow="false"/>
        <light diffuse="0.8 0.8 0.8" dir="-0.301511 0.301511 -0.904534" specular="0.3 0.3 0.3" pos="1.5 -1 3" castshadow="false"/>
        <light diffuse="0.8 0.8 0.8" dir="0.316228 0 -0.948683" specular="0.3 0.3 0.3" pos="-1. 0 3" castshadow="false"/>
        <light diffuse="0.8 0.8 0.8" dir="0.316228 0 -0.948683" specular="0.3 0.3 0.3" pos="-1. -1 3" castshadow="false"/>

        <geom material="MatGnd" name="ground" size="5 5 10" type="plane"/>

        <geom material="light_wood_v3" name="table" pos="0.87 0 0.13" type="box" size="0.8 2 0.13" group = "1" rgba=".5 .5 .5 1" />

        <body name="base" pos="0 0 0">
            <body name="controller_box" pos="0 0 0">
                <inertial diaginertia="1.71363 1.27988 0.809981" mass="46.64" pos="-0.325 0 -0.38"/>
                <geom material="marble" pos="-0.13 0 0.13" size="0.2 0.3 0.13" type="box" name="controller_box_col" rgba="0.5 1.0 1.0 1"/>
            </body>
            <body name="panda0_link0" pos="0 0 0.26" euler="0 0 0">
                <inertial diaginertia="0.122527 0.11364 0.0827785" mass="2.91242" pos="0 0 0"/>
                <geom class="visual" type="mesh" mesh="kuka_link_0_mesh" material="kuka_grey"/>
                <body name="panda0_link1" pos="0 0 0.1575">
                    <inertial euler="0 0 0" pos="0 -0.03 0.12" mass="5.76" diaginertia="0.033 0.0333 0.0123"/>
                    <joint axis="0 0 1" name="panda0_joint1" limited="true" range="-2.96705972839 2.96705972839"/>
                    <geom class="visual" type="mesh" mesh="kuka_link_1_mesh" material="kuka_grey"/>
                    <geom class="collision" type="mesh" mesh="kuka_link_1_mesh" />
                    <body name="panda0_link2" euler="1.570796326794897 3.141592653589793 0" pos="0 0 0.2025">
                        <inertial euler="0 0 0" pos="0.0003 0.059 0.042" mass="6.35" diaginertia="0.0305 0.0304 0.011"/>
                        <joint axis="0 0 1" name="panda0_joint2" pos="0 0 0" limited="true" range="-2.09439510239 2.09439510239"/>
                        <geom class="collision" type="mesh" mesh="kuka_link_2_mesh"/>
                        <geom class="visual" type="mesh" mesh="kuka_link_2_mesh" material="kuka_orange"/>
                        <body name="panda0_link3" euler="1.570796326794897 3.141592653589793 0" pos="0 0.2045 0">
                            <inertial euler="0 0 0" pos="0 0.03 0.13" mass="3.5" diaginertia="0.025 0.0238 0.0076"/>
                            <joint axis="0 0 1" name="panda0_joint3" limited="true" range="-2.96705972839 2.96705972839"/>
                            <geom class="collision" type="mesh" mesh="kuka_link_3_mesh"/>
                            <geom class="visual" type="mesh" mesh="kuka_link_3_mesh" material="kuka_grey"/>
                            <body name="panda0_link4" euler="1.570796326794897 0 0" pos="0 0 0.2155">
                                <inertial euler="0 0 0" pos="0 0.067 0.034" mass="3.5" diaginertia="0.017 0.0164 0.006"/>
                                <joint axis="0 0 1" name="panda0_joint4" limited="true" range="-2.09439510239 2.09439510239"/>
                                <geom class="collision" type="mesh" mesh="kuka_link_4_mesh"/>
                                <geom class="visual" type="mesh" mesh="kuka_link_4_mesh" material="kuka_orange"/>
                                <body name="panda0_link5" euler="-1.570796326794897 0 3.141592653589793" pos="0 0.1845 0">
                                   <inertial euler="0 0 0" pos="0.0001 0.021 0.076" mass="3.5" diaginertia="0.01 0.0087 0.00449"/>
                                    <joint axis="0 0 1" name="panda0_joint5" limited="true" range="-2.96705972839 2.96705972839"/>
                                    <geom class="collision" type="mesh" mesh="kuka_link_5_mesh"/>
                                    <geom class="visual" type="mesh" mesh="kuka_link_5_mesh" material="kuka_grey"/>
                                    <body name="panda0_link6" euler="1.570796326794897 0 0" pos="0 0 0.2155">
                                        <inertial euler="0 0 0" pos="0 0.0006 0.0004" mass="1.8" diaginertia="0.0049 0.0047 0.0036"/>
                                        <joint axis="0 0 1" name="panda0_joint6" limited="true" range="-2.09439510239 2.09439510239"/>
                                        <geom class="collision" type="mesh" mesh="kuka_link_6_mesh"/>
                                        <geom class="visual" type="mesh" mesh="kuka_link_6_mesh" material="kuka_orange"/>
                                        <body name="panda0_link7" euler="-1.570796326794897 0 0" pos="0 0.081 0">
                                            <inertial euler="0 0 0" pos="0 0 0.02" mass="1.2" diaginertia="0.001 0.001 0.001"/>
                                            <joint axis="0 0 1" name="panda0_joint7" limited="true" range="-3.05432619099 3.05432619099"/>
                                            <site name="ee_joint" quat="1 0 0 0" pos="0 0 0.04" type="cylinder" size="0.045 0.001" rgba="1 0 1 0.8" />
                                            <site name="sensor_range" quat="1 0 0 0" pos="0 0 0.08" type="cylinder" size="0.04 0.04" rgba="0 1 1 0.2" />
                                            <!-- <geom name="ee_plane" quat="1 0 0 0" pos="0 0 0.104" type="cylinder" size="0.06 0.001" rgba="1 1 1 1"/> -->
                                            <geom class="collision" type="mesh" mesh="kuka_link_7_mesh"/>
                                            <geom class="visual" type="mesh" mesh="kuka_link_7_mesh" material="kuka_grey"/>

                                        </body>
                                    </body>
                                </body>
                            </body>
                        </body>
                    </body>
                </body>
            </body>
        </body>

        <body name="object" pos="0.6 -1.5 0.37" quat="1 0 0 0" >
            <inertial pos="0 0 0" mass="10" diaginertia="0.0003686049833333333 0.001255996129167 0.001460916979167" />
<!--            <joint axis="1 0 0" name="box:slidex" damping="0.1" type="slide"/>-->
            <joint axis="0 1 0" name="box:slidey" type="slide"/>
<!--            <joint axis="0 0 1" name="box:slidez" damping="0.5" type="slide"/>-->
            <geom name="object" type="box" size="0.16 0.08 0.1" group="1" rgba=".9 0 0 1" />
<!--            <site name="obj_front" pos="-0.1605 0 0" quat="1 0 0 0"          type="box" size="1e-5 0.04 0.09" group="2" rgba="1 1 0 0.5" />-->
<!--            <site name="obj_right" pos="0 -0.0805 0" quat="0.707 0 0 0.707"  type="box" size="1e-5 0.10 0.09" group="2" rgba="0 1 0 0.5" />-->
            <site name="obj_contact"  pos="0 +0.0805 0" quat="0.707 0 0 -0.707" type="box" size="1e-5 0.10 0.09" group="2" rgba="1 0 1 0.5" />
<!--            <site name="obj_rear"  pos="+0.1605 0 0" quat="0 0 0 1"          type="box" size="1e-5 0.04 0.09" group="2" rgba="1 1 0 0.5" />-->
            <!-- Point contact sites -->
            <!-- <site name="obj_front" pos="-0.15075 0 0" quat="1 0 0 0"          type="sphere" size="1e-3" group="2" rgba="1 1 0 1" /> -->
            <!-- <site name="obj_right" pos="0 -0.0745 0"  quat="0.707 0 0 0.707"  type="sphere" size="1e-3" group="2" rgba="1 1 0 1" /> -->
            <!-- <site name="obj_left"  pos="0 +0.0745 0"  quat="0.707 0 0 -0.707" type="sphere" size="1e-3" group="2" rgba="1 1 0 1" /> -->
            <!-- <site name="obj_rear"  pos="+0.15075 0 0" quat="0 0 0 1"          type="sphere" size="1e-3" group="2" rgba="1 1 0 1" /> -->
        </body>

        <site name="slide_bar" pos="0.6 0 0.27" type="box" size="0.05 2 0.01" rgba=".0 .0 .5 .15"/>

    </worldbody>
    <actuator>
        <general ctrllimited="true" ctrlrange="-300.0 300.0" joint="panda0_joint1" name="panda0_joint1"/>
        <general ctrllimited="true" ctrlrange="-300.0 300.0" joint="panda0_joint2" name="panda0_joint2"/>
        <general ctrllimited="true" ctrlrange="-300.0 300.0" joint="panda0_joint3" name="panda0_joint3"/>
        <general ctrllimited="true" ctrlrange="-300.0 300.0" joint="panda0_joint4" name="panda0_joint4"/>
        <general ctrllimited="true" ctrlrange="-300.0 300.0" joint="panda0_joint5" name="panda0_joint5"/>
        <general ctrllimited="true" ctrlrange="-300.0 300.0" joint="panda0_joint6" name="panda0_joint6"/>
        <general ctrllimited="true" ctrlrange="-300.0 300.0" joint="panda0_joint7" name="panda0_joint7"/>
<!--        <motor gear="100.0" joint="box:slidex"/>-->
        <motor gear="100.0" joint="box:slidey"/>
<!--        <motor gear="100.0" joint="box:slidez"/>-->
    </actuator>
    <sensor>
        <jointpos joint="panda0_joint1" name="fr_arm_jp1"/>
        <jointpos joint="panda0_joint2" name="fr_arm_jp2"/>
        <jointpos joint="panda0_joint3" name="fr_arm_jp3"/>
        <jointpos joint="panda0_joint4" name="fr_arm_jp4"/>
        <jointpos joint="panda0_joint5" name="fr_arm_jp5"/>
        <jointpos joint="panda0_joint6" name="fr_arm_jp6"/>
        <jointpos joint="panda0_joint7" name="fr_arm_jp7"/>
<!--        <jointpos joint="box:slidex" name="box_jpx"/>-->
        <jointpos joint="box:slidey" name="box_jpy"/>
<!--        <jointpos joint="box:slidez" name="box_jpz"/>-->

        <jointvel joint="panda0_joint1" name="fr_arm_jv1"/>
        <jointvel joint="panda0_joint2" name="fr_arm_jv2"/>
        <jointvel joint="panda0_joint3" name="fr_arm_jv3"/>
        <jointvel joint="panda0_joint4" name="fr_arm_jv4"/>
        <jointvel joint="panda0_joint5" name="fr_arm_jv5"/>
        <jointvel joint="panda0_joint6" name="fr_arm_jv6"/>
        <jointvel joint="panda0_joint7" name="fr_arm_jv7"/>
<!--        <jointvel joint="box:slidex" name="box_jvx"/>-->
        <jointvel joint="box:slidey" name="box_jvy"/>
<!--        <jointvel joint="box:slidez" name="box_jvz"/>-->

        <actuatorfrc actuator="panda0_joint1" name="fr_arm_jf1"/>
        <actuatorfrc actuator="panda0_joint2" name="fr_arm_jf2"/>
        <actuatorfrc actuator="panda0_joint3" name="fr_arm_jf3"/>
        <actuatorfrc actuator="panda0_joint4" name="fr_arm_jf4"/>
        <actuatorfrc actuator="panda0_joint5" name="fr_arm_jf5"/>
        <actuatorfrc actuator="panda0_joint6" name="fr_arm_jf6"/>
        <actuatorfrc actuator="panda0_joint7" name="fr_arm_jf7"/>
    </sensor>
<!--    <keyframe>-->
<!--        <key qpos="0.0 0.74 0.0 -1.7 -1.62 1.6 0.0 0.0 0.0 0.0" qvel="0.0 0.0 0.0 0.0 0.0 0.0 0.0 0.0 0.0 0.0" time="0.0"/>-->
<!--    </keyframe>-->
</mujoco>
